<?xml version="1.0"?>
<robot xmlns:xacro="http://www.ros.org/wiki/xacro">

	<xacro:property name="wheel_effort" value="1000000" />

	<xacro:include filename="$(find maddrive_urdf_tools)/urdf/macros/inertia.urdf.xacro" />
	<xacro:include filename="$(find maddrive_urdf_tools)/urdf/macros/common.urdf.xacro" />

	<!-- BASE WHEEL -->
	<xacro:macro name="base_wheel" params="name">
		<link name="${name}">
			<visual>
				<origin xyz="0 0 0" rpy="${pi/2} 0 0" />
				<geometry>
					<cylinder length="${wheel_width}" radius="${wheel_radius}" />
				</geometry>
			</visual>
			<collision>
				<origin xyz="0 0 0" rpy="${pi/2} 0 0" />
				<geometry>
					<cylinder length="${wheel_width}" radius="${wheel_radius}" />
				</geometry>
			</collision>
			<xacro:cylinder_inertia r="${wheel_radius}" h="${wheel_width}" mass="${wheel_mass}">
				<origin xyz="0 0 0" rpy="${pi/2} 0 0" />
			</xacro:cylinder_inertia>
		</link>
		<gazebo reference="${name}">
			<material>Gazebo/Black</material>
		</gazebo>
	</xacro:macro>

	<!-- SPEED WHEEL -->
	<xacro:macro name="speed_wheel" params="name base_name xyz ">
		<xacro:base_wheel name="wheel_${name}" />

		<joint name="${name}_speed_joint" type="continuous">
			<parent link="${base_name}" />
			<child link="wheel_${name}" />
			<origin xyz="${xyz}" rpy="0 0 0" />
			<axis xyz="0 1 0" />
			<limit effort="${wheel_effort}" velocity="0" />
		</joint>
	</xacro:macro>

	<!-- STEER WHEEL -->
	<xacro:macro name="steer_wheel" params="name base_name xyz steer_limit">
		<xacro:base_wheel name="wheel_${name}" />

		<link name="steer_${name}">
			<xacro:null_inertial />
		</link>

		<joint name="${name}_steer_joint" type="revolute">
			<parent link="${base_name}" />
			<child link="steer_${name}" />
			<origin xyz="${xyz}" rpy="0 0 0" />
			<axis xyz="0 0 1" />
			<limit lower="${-steer_limit}" upper="${steer_limit}" effort="${wheel_effort}" velocity="0" />
		</joint>

		<joint name="${name}_speed_joint" type="continuous">
			<parent link="steer_${name}" />
			<child link="wheel_${name}" />
			<origin xyz="0 0 0" rpy="0 0 0" />
			<axis xyz="0 1 0" />
			<limit effort="${wheel_effort}" velocity="0" />
		</joint>
	</xacro:macro>
</robot>